ERROR [2018-02-05 20:29:56] /vagrant/testapp01/framework/account/http.py 42 _http_request 12446 140350672860928 
 	 login http request error! type: GET, url: http://paaskghk.jingle.cn/login/accounts/is_login/, data: {'bk_token': 'ppeHTTNJOvu22SwpFAW9jFaWLIQvgNem6YtgnuFSvIo'} 
Traceback (most recent call last):
  File "/vagrant/testapp01/framework/account/http.py", line 30, in _http_request
    resp = requests.get(url=url, headers=headers, params=data)
  File "/usr/lib/python2.7/site-packages/requests/api.py", line 55, in get
    return request('get', url, **kwargs)
  File "/usr/lib/python2.7/site-packages/requests/api.py", line 44, in request
    return session.request(method=method, url=url, **kwargs)
  File "/usr/lib/python2.7/site-packages/requests/sessions.py", line 361, in request
    resp = self.send(prep, **send_kwargs)
  File "/usr/lib/python2.7/site-packages/requests/sessions.py", line 464, in send
    r = adapter.send(request, **kwargs)
  File "/usr/lib/python2.7/site-packages/requests/adapters.py", line 356, in send
    raise ConnectionError(e)
ConnectionError: HTTPConnectionPool(host='paaskghk.jingle.cn', port=80): Max retries exceeded with url: /login/accounts/is_login/?bk_token=ppeHTTNJOvu22SwpFAW9jFaWLIQvgNem6YtgnuFSvIo (Caused by <class 'socket.error'>: [Errno 111] Connection refused)
INFO [2018-02-05 20:29:56] /vagrant/testapp01/framework/account/accounts.py 86 verify_bk_login 12446 140350672860928 
 	 验证用户登录token无效： 

ERROR [2018-02-05 20:29:59] /vagrant/testapp01/framework/account/http.py 42 _http_request 12446 140350660183808 
 	 login http request error! type: GET, url: http://paaskghk.jingle.cn/login/accounts/is_login/, data: {'bk_token': 'CXWR94N8SYeLuBGU7at9VTabqey432p40L0L8yaDAy0'} 
Traceback (most recent call last):
  File "/vagrant/testapp01/framework/account/http.py", line 30, in _http_request
    resp = requests.get(url=url, headers=headers, params=data)
  File "/usr/lib/python2.7/site-packages/requests/api.py", line 55, in get
    return request('get', url, **kwargs)
  File "/usr/lib/python2.7/site-packages/requests/api.py", line 44, in request
    return session.request(method=method, url=url, **kwargs)
  File "/usr/lib/python2.7/site-packages/requests/sessions.py", line 361, in request
    resp = self.send(prep, **send_kwargs)
  File "/usr/lib/python2.7/site-packages/requests/sessions.py", line 464, in send
    r = adapter.send(request, **kwargs)
  File "/usr/lib/python2.7/site-packages/requests/adapters.py", line 356, in send
    raise ConnectionError(e)
ConnectionError: HTTPConnectionPool(host='paaskghk.jingle.cn', port=80): Max retries exceeded with url: /login/accounts/is_login/?bk_token=CXWR94N8SYeLuBGU7at9VTabqey432p40L0L8yaDAy0 (Caused by <class 'socket.error'>: [Errno 111] Connection refused)
INFO [2018-02-05 20:29:59] /vagrant/testapp01/framework/account/accounts.py 86 verify_bk_login 12446 140350660183808 
 	 验证用户登录token无效： 

ERROR [2018-02-05 20:30:13] /vagrant/testapp01/framework/account/http.py 42 _http_request 12446 140350660183808 
 	 login http request error! type: GET, url: http://paaskghk.jingle.cn/login/accounts/is_login/, data: {'bk_token': 'V2rb506SzBR2nwGqEz7Zq8JP-Lch5BXLBxRyAJ7x-qQ'} 
Traceback (most recent call last):
  File "/vagrant/testapp01/framework/account/http.py", line 30, in _http_request
    resp = requests.get(url=url, headers=headers, params=data)
  File "/usr/lib/python2.7/site-packages/requests/api.py", line 55, in get
    return request('get', url, **kwargs)
  File "/usr/lib/python2.7/site-packages/requests/api.py", line 44, in request
    return session.request(method=method, url=url, **kwargs)
  File "/usr/lib/python2.7/site-packages/requests/sessions.py", line 361, in request
    resp = self.send(prep, **send_kwargs)
  File "/usr/lib/python2.7/site-packages/requests/sessions.py", line 464, in send
    r = adapter.send(request, **kwargs)
  File "/usr/lib/python2.7/site-packages/requests/adapters.py", line 356, in send
    raise ConnectionError(e)
ConnectionError: HTTPConnectionPool(host='paaskghk.jingle.cn', port=80): Max retries exceeded with url: /login/accounts/is_login/?bk_token=V2rb506SzBR2nwGqEz7Zq8JP-Lch5BXLBxRyAJ7x-qQ (Caused by <class 'socket.error'>: [Errno 111] Connection refused)
INFO [2018-02-05 20:30:13] /vagrant/testapp01/framework/account/accounts.py 86 verify_bk_login 12446 140350660183808 
 	 验证用户登录token无效： 

ERROR [2018-02-05 20:30:18] /vagrant/testapp01/framework/account/http.py 42 _http_request 12446 140350660183808 
 	 login http request error! type: GET, url: http://paaskghk.jingle.cn/login/accounts/is_login/, data: {'bk_token': 'Txuk4NmxuxmyeUy9Lnp2Wg1BNrM0nNeicC_i_l4u1Oc'} 
Traceback (most recent call last):
  File "/vagrant/testapp01/framework/account/http.py", line 30, in _http_request
    resp = requests.get(url=url, headers=headers, params=data)
  File "/usr/lib/python2.7/site-packages/requests/api.py", line 55, in get
    return request('get', url, **kwargs)
  File "/usr/lib/python2.7/site-packages/requests/api.py", line 44, in request
    return session.request(method=method, url=url, **kwargs)
  File "/usr/lib/python2.7/site-packages/requests/sessions.py", line 361, in request
    resp = self.send(prep, **send_kwargs)
  File "/usr/lib/python2.7/site-packages/requests/sessions.py", line 464, in send
    r = adapter.send(request, **kwargs)
  File "/usr/lib/python2.7/site-packages/requests/adapters.py", line 356, in send
    raise ConnectionError(e)
ConnectionError: HTTPConnectionPool(host='paaskghk.jingle.cn', port=80): Max retries exceeded with url: /login/accounts/is_login/?bk_token=Txuk4NmxuxmyeUy9Lnp2Wg1BNrM0nNeicC_i_l4u1Oc (Caused by <class 'socket.error'>: [Errno 111] Connection refused)
INFO [2018-02-05 20:30:18] /vagrant/testapp01/framework/account/accounts.py 86 verify_bk_login 12446 140350660183808 
 	 验证用户登录token无效： 

ERROR [2018-02-05 20:30:25] /vagrant/testapp01/framework/account/http.py 42 _http_request 12446 140350660183808 
 	 login http request error! type: GET, url: http://paaskghk.jingle.cn/login/accounts/is_login/, data: {'bk_token': 'cWLdlAfx9JYsSJuhkpGbXOJaU_roHkdGOoKkOUMiirw'} 
Traceback (most recent call last):
  File "/vagrant/testapp01/framework/account/http.py", line 30, in _http_request
    resp = requests.get(url=url, headers=headers, params=data)
  File "/usr/lib/python2.7/site-packages/requests/api.py", line 55, in get
    return request('get', url, **kwargs)
  File "/usr/lib/python2.7/site-packages/requests/api.py", line 44, in request
    return session.request(method=method, url=url, **kwargs)
  File "/usr/lib/python2.7/site-packages/requests/sessions.py", line 361, in request
    resp = self.send(prep, **send_kwargs)
  File "/usr/lib/python2.7/site-packages/requests/sessions.py", line 464, in send
    r = adapter.send(request, **kwargs)
  File "/usr/lib/python2.7/site-packages/requests/adapters.py", line 356, in send
    raise ConnectionError(e)
ConnectionError: HTTPConnectionPool(host='paaskghk.jingle.cn', port=80): Max retries exceeded with url: /login/accounts/is_login/?bk_token=cWLdlAfx9JYsSJuhkpGbXOJaU_roHkdGOoKkOUMiirw (Caused by <class 'socket.error'>: [Errno 111] Connection refused)
INFO [2018-02-05 20:30:25] /vagrant/testapp01/framework/account/accounts.py 86 verify_bk_login 12446 140350660183808 
 	 验证用户登录token无效： 

ERROR [2018-02-05 20:32:25] /vagrant/testapp01/framework/account/http.py 42 _http_request 12446 140350660183808 
 	 login http request error! type: GET, url: http://paaskghk.jingle.cn/login/accounts/is_login/, data: {'bk_token': 'mj61RCpjQ6NDcKKjjTFw2bEDJPNjUpU6nO-6OEwgcY0'} 
Traceback (most recent call last):
  File "/vagrant/testapp01/framework/account/http.py", line 30, in _http_request
    resp = requests.get(url=url, headers=headers, params=data)
  File "/usr/lib/python2.7/site-packages/requests/api.py", line 55, in get
    return request('get', url, **kwargs)
  File "/usr/lib/python2.7/site-packages/requests/api.py", line 44, in request
    return session.request(method=method, url=url, **kwargs)
  File "/usr/lib/python2.7/site-packages/requests/sessions.py", line 361, in request
    resp = self.send(prep, **send_kwargs)
  File "/usr/lib/python2.7/site-packages/requests/sessions.py", line 464, in send
    r = adapter.send(request, **kwargs)
  File "/usr/lib/python2.7/site-packages/requests/adapters.py", line 356, in send
    raise ConnectionError(e)
ConnectionError: HTTPConnectionPool(host='paaskghk.jingle.cn', port=80): Max retries exceeded with url: /login/accounts/is_login/?bk_token=mj61RCpjQ6NDcKKjjTFw2bEDJPNjUpU6nO-6OEwgcY0 (Caused by <class 'socket.error'>: [Errno 111] Connection refused)
INFO [2018-02-05 20:32:25] /vagrant/testapp01/framework/account/accounts.py 86 verify_bk_login 12446 140350660183808 
 	 验证用户登录token无效： 

ERROR [2018-02-05 20:32:42] /vagrant/testapp01/framework/account/http.py 42 _http_request 12446 140350660183808 
 	 login http request error! type: GET, url: http://paaskghk.jingle.cn/login/accounts/is_login/, data: {'bk_token': '7gKgF3WmzhDFuhfEZBpRLxX7YaN_0ONuug4WBd3RNa8'} 
Traceback (most recent call last):
  File "/vagrant/testapp01/framework/account/http.py", line 30, in _http_request
    resp = requests.get(url=url, headers=headers, params=data)
  File "/usr/lib/python2.7/site-packages/requests/api.py", line 55, in get
    return request('get', url, **kwargs)
  File "/usr/lib/python2.7/site-packages/requests/api.py", line 44, in request
    return session.request(method=method, url=url, **kwargs)
  File "/usr/lib/python2.7/site-packages/requests/sessions.py", line 361, in request
    resp = self.send(prep, **send_kwargs)
  File "/usr/lib/python2.7/site-packages/requests/sessions.py", line 464, in send
    r = adapter.send(request, **kwargs)
  File "/usr/lib/python2.7/site-packages/requests/adapters.py", line 356, in send
    raise ConnectionError(e)
ConnectionError: HTTPConnectionPool(host='paaskghk.jingle.cn', port=80): Max retries exceeded with url: /login/accounts/is_login/?bk_token=7gKgF3WmzhDFuhfEZBpRLxX7YaN_0ONuug4WBd3RNa8 (Caused by <class 'socket.error'>: [Errno 111] Connection refused)
INFO [2018-02-05 20:32:42] /vagrant/testapp01/framework/account/accounts.py 86 verify_bk_login 12446 140350660183808 
 	 验证用户登录token无效： 

ERROR [2018-02-05 20:39:45] /vagrant/testapp01/framework/account/http.py 42 _http_request 12446 140350660183808 
 	 login http request error! type: GET, url: http://paaskghk.jingle.cn/login/accounts/is_login/, data: {'bk_token': '7qv6xwpD1KiPV-wwqgO8OP_kLHdlxZZ28Km7NFyF6uQ'} 
Traceback (most recent call last):
  File "/vagrant/testapp01/framework/account/http.py", line 30, in _http_request
    resp = requests.get(url=url, headers=headers, params=data)
  File "/usr/lib/python2.7/site-packages/requests/api.py", line 55, in get
    return request('get', url, **kwargs)
  File "/usr/lib/python2.7/site-packages/requests/api.py", line 44, in request
    return session.request(method=method, url=url, **kwargs)
  File "/usr/lib/python2.7/site-packages/requests/sessions.py", line 361, in request
    resp = self.send(prep, **send_kwargs)
  File "/usr/lib/python2.7/site-packages/requests/sessions.py", line 464, in send
    r = adapter.send(request, **kwargs)
  File "/usr/lib/python2.7/site-packages/requests/adapters.py", line 356, in send
    raise ConnectionError(e)
ConnectionError: HTTPConnectionPool(host='paaskghk.jingle.cn', port=80): Max retries exceeded with url: /login/accounts/is_login/?bk_token=7qv6xwpD1KiPV-wwqgO8OP_kLHdlxZZ28Km7NFyF6uQ (Caused by <class 'socket.error'>: [Errno 111] Connection refused)
INFO [2018-02-05 20:39:45] /vagrant/testapp01/framework/account/accounts.py 86 verify_bk_login 12446 140350660183808 
 	 验证用户登录token无效： 

ERROR [2018-02-05 20:45:38] /vagrant/testapp01/framework/account/http.py 42 _http_request 12891 140576013846272 
 	 login http request error! type: GET, url: http://paaskghk.jingle.cn/login/accounts/is_login/, data: {'bk_token': 'dKm2G0Yy8OGhl26zv_v_wnjHZkUzuBP4puHKvhP0dv8'} 
Traceback (most recent call last):
  File "/vagrant/testapp01/framework/account/http.py", line 30, in _http_request
    resp = requests.get(url=url, headers=headers, params=data)
  File "/usr/lib/python2.7/site-packages/requests/api.py", line 55, in get
    return request('get', url, **kwargs)
  File "/usr/lib/python2.7/site-packages/requests/api.py", line 44, in request
    return session.request(method=method, url=url, **kwargs)
  File "/usr/lib/python2.7/site-packages/requests/sessions.py", line 361, in request
    resp = self.send(prep, **send_kwargs)
  File "/usr/lib/python2.7/site-packages/requests/sessions.py", line 464, in send
    r = adapter.send(request, **kwargs)
  File "/usr/lib/python2.7/site-packages/requests/adapters.py", line 356, in send
    raise ConnectionError(e)
ConnectionError: HTTPConnectionPool(host='paaskghk.jingle.cn', port=80): Max retries exceeded with url: /login/accounts/is_login/?bk_token=dKm2G0Yy8OGhl26zv_v_wnjHZkUzuBP4puHKvhP0dv8 (Caused by <class 'socket.error'>: [Errno 111] Connection refused)
INFO [2018-02-05 20:45:38] /vagrant/testapp01/framework/account/accounts.py 86 verify_bk_login 12891 140576013846272 
 	 验证用户登录token无效： 

ERROR [2018-02-05 20:45:40] /vagrant/testapp01/framework/account/http.py 42 _http_request 12891 140576013846272 
 	 login http request error! type: GET, url: http://paaskghk.jingle.cn/login/accounts/is_login/, data: {'bk_token': 'buXjdq_beV-Z6pAMIstU0vawLN_930sjTR-az0V6RJI'} 
Traceback (most recent call last):
  File "/vagrant/testapp01/framework/account/http.py", line 30, in _http_request
    resp = requests.get(url=url, headers=headers, params=data)
  File "/usr/lib/python2.7/site-packages/requests/api.py", line 55, in get
    return request('get', url, **kwargs)
  File "/usr/lib/python2.7/site-packages/requests/api.py", line 44, in request
    return session.request(method=method, url=url, **kwargs)
  File "/usr/lib/python2.7/site-packages/requests/sessions.py", line 361, in request
    resp = self.send(prep, **send_kwargs)
  File "/usr/lib/python2.7/site-packages/requests/sessions.py", line 464, in send
    r = adapter.send(request, **kwargs)
  File "/usr/lib/python2.7/site-packages/requests/adapters.py", line 356, in send
    raise ConnectionError(e)
ConnectionError: HTTPConnectionPool(host='paaskghk.jingle.cn', port=80): Max retries exceeded with url: /login/accounts/is_login/?bk_token=buXjdq_beV-Z6pAMIstU0vawLN_930sjTR-az0V6RJI (Caused by <class 'socket.error'>: [Errno 111] Connection refused)
INFO [2018-02-05 20:45:40] /vagrant/testapp01/framework/account/accounts.py 86 verify_bk_login 12891 140576013846272 
 	 验证用户登录token无效： 

ERROR [2018-02-05 20:45:47] /vagrant/testapp01/framework/account/http.py 42 _http_request 12891 140576013846272 
 	 login http request error! type: GET, url: http://paaskghk.jingle.cn/login/accounts/is_login/, data: {'bk_token': '96Osn-jzwC7YVz032E1TjF_KIqXRI-dYabZ7e9sGSNE'} 
Traceback (most recent call last):
  File "/vagrant/testapp01/framework/account/http.py", line 30, in _http_request
    resp = requests.get(url=url, headers=headers, params=data)
  File "/usr/lib/python2.7/site-packages/requests/api.py", line 55, in get
    return request('get', url, **kwargs)
  File "/usr/lib/python2.7/site-packages/requests/api.py", line 44, in request
    return session.request(method=method, url=url, **kwargs)
  File "/usr/lib/python2.7/site-packages/requests/sessions.py", line 361, in request
    resp = self.send(prep, **send_kwargs)
  File "/usr/lib/python2.7/site-packages/requests/sessions.py", line 464, in send
    r = adapter.send(request, **kwargs)
  File "/usr/lib/python2.7/site-packages/requests/adapters.py", line 356, in send
    raise ConnectionError(e)
ConnectionError: HTTPConnectionPool(host='paaskghk.jingle.cn', port=80): Max retries exceeded with url: /login/accounts/is_login/?bk_token=96Osn-jzwC7YVz032E1TjF_KIqXRI-dYabZ7e9sGSNE (Caused by <class 'socket.error'>: [Errno 111] Connection refused)
INFO [2018-02-05 20:45:47] /vagrant/testapp01/framework/account/accounts.py 86 verify_bk_login 12891 140576013846272 
 	 验证用户登录token无效： 

ERROR [2018-02-05 20:56:35] /vagrant/testapp01/framework/account/http.py 42 _http_request 13060 140521121142528 
 	 login http request error! type: GET, url: http://paaskghk.jingle.cn/login/accounts/is_login/, data: {'bk_token': 'lH52A43nqNnGQ468E8hxF-nvWf4CZjUsu0JzpRMkRQU'} 
Traceback (most recent call last):
  File "/vagrant/testapp01/framework/account/http.py", line 30, in _http_request
    resp = requests.get(url=url, headers=headers, params=data)
  File "/usr/lib/python2.7/site-packages/requests/api.py", line 55, in get
    return request('get', url, **kwargs)
  File "/usr/lib/python2.7/site-packages/requests/api.py", line 44, in request
    return session.request(method=method, url=url, **kwargs)
  File "/usr/lib/python2.7/site-packages/requests/sessions.py", line 361, in request
    resp = self.send(prep, **send_kwargs)
  File "/usr/lib/python2.7/site-packages/requests/sessions.py", line 464, in send
    r = adapter.send(request, **kwargs)
  File "/usr/lib/python2.7/site-packages/requests/adapters.py", line 356, in send
    raise ConnectionError(e)
ConnectionError: HTTPConnectionPool(host='paaskghk.jingle.cn', port=80): Max retries exceeded with url: /login/accounts/is_login/?bk_token=lH52A43nqNnGQ468E8hxF-nvWf4CZjUsu0JzpRMkRQU (Caused by <class 'socket.error'>: [Errno 111] Connection refused)
INFO [2018-02-05 20:56:35] /vagrant/testapp01/framework/account/accounts.py 86 verify_bk_login 13060 140521121142528 
 	 验证用户登录token无效： 

ERROR [2018-02-05 20:56:36] /vagrant/testapp01/framework/account/http.py 42 _http_request 13060 140521121142528 
 	 login http request error! type: GET, url: http://paaskghk.jingle.cn/login/accounts/is_login/, data: {'bk_token': 'QoIWcyrtBqAbAl21svLkVZpZ1Ak1WEFEw9KfZmg7hdA'} 
Traceback (most recent call last):
  File "/vagrant/testapp01/framework/account/http.py", line 30, in _http_request
    resp = requests.get(url=url, headers=headers, params=data)
  File "/usr/lib/python2.7/site-packages/requests/api.py", line 55, in get
    return request('get', url, **kwargs)
  File "/usr/lib/python2.7/site-packages/requests/api.py", line 44, in request
    return session.request(method=method, url=url, **kwargs)
  File "/usr/lib/python2.7/site-packages/requests/sessions.py", line 361, in request
    resp = self.send(prep, **send_kwargs)
  File "/usr/lib/python2.7/site-packages/requests/sessions.py", line 464, in send
    r = adapter.send(request, **kwargs)
  File "/usr/lib/python2.7/site-packages/requests/adapters.py", line 356, in send
    raise ConnectionError(e)
ConnectionError: HTTPConnectionPool(host='paaskghk.jingle.cn', port=80): Max retries exceeded with url: /login/accounts/is_login/?bk_token=QoIWcyrtBqAbAl21svLkVZpZ1Ak1WEFEw9KfZmg7hdA (Caused by <class 'socket.error'>: [Errno 111] Connection refused)
INFO [2018-02-05 20:56:36] /vagrant/testapp01/framework/account/accounts.py 86 verify_bk_login 13060 140521121142528 
 	 验证用户登录token无效： 

ERROR [2018-02-05 21:02:37] /vagrant/testapp01/framework/account/http.py 42 _http_request 13060 140521121142528 
 	 login http request error! type: GET, url: http://paaskghk.jingle.cn/login/accounts/is_login/, data: {'bk_token': '_ESCRWX8fd6OONuEe5eauWXYQbmj0-uA_dP6bdZ6Zms'} 
Traceback (most recent call last):
  File "/vagrant/testapp01/framework/account/http.py", line 30, in _http_request
    resp = requests.get(url=url, headers=headers, params=data)
  File "/usr/lib/python2.7/site-packages/requests/api.py", line 55, in get
    return request('get', url, **kwargs)
  File "/usr/lib/python2.7/site-packages/requests/api.py", line 44, in request
    return session.request(method=method, url=url, **kwargs)
  File "/usr/lib/python2.7/site-packages/requests/sessions.py", line 361, in request
    resp = self.send(prep, **send_kwargs)
  File "/usr/lib/python2.7/site-packages/requests/sessions.py", line 464, in send
    r = adapter.send(request, **kwargs)
  File "/usr/lib/python2.7/site-packages/requests/adapters.py", line 356, in send
    raise ConnectionError(e)
ConnectionError: HTTPConnectionPool(host='paaskghk.jingle.cn', port=80): Max retries exceeded with url: /login/accounts/is_login/?bk_token=_ESCRWX8fd6OONuEe5eauWXYQbmj0-uA_dP6bdZ6Zms (Caused by <class 'socket.error'>: [Errno 111] Connection refused)
INFO [2018-02-05 21:02:37] /vagrant/testapp01/framework/account/accounts.py 86 verify_bk_login 13060 140521121142528 
 	 验证用户登录token无效： 

ERROR [2018-02-05 21:07:08] /vagrant/testapp01/framework/account/http.py 42 _http_request 13060 140521121142528 
 	 login http request error! type: GET, url: http://paaskghk.jingle.cn/login/accounts/is_login/, data: {'bk_token': 'geJ95BEp5cCj6jCG586q8QlSx4mayMf1hx_GAKVWE2o'} 
Traceback (most recent call last):
  File "/vagrant/testapp01/framework/account/http.py", line 30, in _http_request
    resp = requests.get(url=url, headers=headers, params=data)
  File "/usr/lib/python2.7/site-packages/requests/api.py", line 55, in get
    return request('get', url, **kwargs)
  File "/usr/lib/python2.7/site-packages/requests/api.py", line 44, in request
    return session.request(method=method, url=url, **kwargs)
  File "/usr/lib/python2.7/site-packages/requests/sessions.py", line 361, in request
    resp = self.send(prep, **send_kwargs)
  File "/usr/lib/python2.7/site-packages/requests/sessions.py", line 464, in send
    r = adapter.send(request, **kwargs)
  File "/usr/lib/python2.7/site-packages/requests/adapters.py", line 356, in send
    raise ConnectionError(e)
ConnectionError: HTTPConnectionPool(host='paaskghk.jingle.cn', port=80): Max retries exceeded with url: /login/accounts/is_login/?bk_token=geJ95BEp5cCj6jCG586q8QlSx4mayMf1hx_GAKVWE2o (Caused by <class 'socket.error'>: [Errno 111] Connection refused)
INFO [2018-02-05 21:07:08] /vagrant/testapp01/framework/account/accounts.py 86 verify_bk_login 13060 140521121142528 
 	 验证用户登录token无效： 

ERROR [2018-02-05 21:07:35] /vagrant/testapp01/framework/account/http.py 42 _http_request 13060 140521121142528 
 	 login http request error! type: GET, url: http://paaskghk.jingle.cn/login/accounts/is_login/, data: {'bk_token': 'breBEyJFKTJRAkCps1w11gSHw7KXyU_yzDG5IzZHruU'} 
Traceback (most recent call last):
  File "/vagrant/testapp01/framework/account/http.py", line 30, in _http_request
    resp = requests.get(url=url, headers=headers, params=data)
  File "/usr/lib/python2.7/site-packages/requests/api.py", line 55, in get
    return request('get', url, **kwargs)
  File "/usr/lib/python2.7/site-packages/requests/api.py", line 44, in request
    return session.request(method=method, url=url, **kwargs)
  File "/usr/lib/python2.7/site-packages/requests/sessions.py", line 361, in request
    resp = self.send(prep, **send_kwargs)
  File "/usr/lib/python2.7/site-packages/requests/sessions.py", line 464, in send
    r = adapter.send(request, **kwargs)
  File "/usr/lib/python2.7/site-packages/requests/adapters.py", line 356, in send
    raise ConnectionError(e)
ConnectionError: HTTPConnectionPool(host='paaskghk.jingle.cn', port=80): Max retries exceeded with url: /login/accounts/is_login/?bk_token=breBEyJFKTJRAkCps1w11gSHw7KXyU_yzDG5IzZHruU (Caused by <class 'socket.error'>: [Errno 111] Connection refused)
INFO [2018-02-05 21:07:35] /vagrant/testapp01/framework/account/accounts.py 86 verify_bk_login 13060 140521121142528 
 	 验证用户登录token无效： 

ERROR [2018-02-05 21:08:45] /vagrant/testapp01/framework/account/http.py 42 _http_request 13060 140521121142528 
 	 login http request error! type: GET, url: http://paaskghk.jingle.cn/login/accounts/is_login/, data: {'bk_token': 'NS3jgjnNz0XMR4A7z3dVVLqMLFuOa3CgC1PnnlXZ2Cc'} 
Traceback (most recent call last):
  File "/vagrant/testapp01/framework/account/http.py", line 30, in _http_request
    resp = requests.get(url=url, headers=headers, params=data)
  File "/usr/lib/python2.7/site-packages/requests/api.py", line 55, in get
    return request('get', url, **kwargs)
  File "/usr/lib/python2.7/site-packages/requests/api.py", line 44, in request
    return session.request(method=method, url=url, **kwargs)
  File "/usr/lib/python2.7/site-packages/requests/sessions.py", line 361, in request
    resp = self.send(prep, **send_kwargs)
  File "/usr/lib/python2.7/site-packages/requests/sessions.py", line 464, in send
    r = adapter.send(request, **kwargs)
  File "/usr/lib/python2.7/site-packages/requests/adapters.py", line 356, in send
    raise ConnectionError(e)
ConnectionError: HTTPConnectionPool(host='paaskghk.jingle.cn', port=80): Max retries exceeded with url: /login/accounts/is_login/?bk_token=NS3jgjnNz0XMR4A7z3dVVLqMLFuOa3CgC1PnnlXZ2Cc (Caused by <class 'socket.error'>: [Errno 111] Connection refused)
INFO [2018-02-05 21:08:45] /vagrant/testapp01/framework/account/accounts.py 86 verify_bk_login 13060 140521121142528 
 	 验证用户登录token无效： 

ERROR [2018-02-05 21:09:52] /vagrant/testapp01/framework/account/http.py 42 _http_request 13060 140521121142528 
 	 login http request error! type: GET, url: http://paaskghk.jingle.cn/login/accounts/is_login/, data: {'bk_token': 'j1SM6C-otCNIRpJx_3UHhvZHSlQf1Dr5_whHUIIZKNc'} 
Traceback (most recent call last):
  File "/vagrant/testapp01/framework/account/http.py", line 30, in _http_request
    resp = requests.get(url=url, headers=headers, params=data)
  File "/usr/lib/python2.7/site-packages/requests/api.py", line 55, in get
    return request('get', url, **kwargs)
  File "/usr/lib/python2.7/site-packages/requests/api.py", line 44, in request
    return session.request(method=method, url=url, **kwargs)
  File "/usr/lib/python2.7/site-packages/requests/sessions.py", line 361, in request
    resp = self.send(prep, **send_kwargs)
  File "/usr/lib/python2.7/site-packages/requests/sessions.py", line 464, in send
    r = adapter.send(request, **kwargs)
  File "/usr/lib/python2.7/site-packages/requests/adapters.py", line 356, in send
    raise ConnectionError(e)
ConnectionError: HTTPConnectionPool(host='paaskghk.jingle.cn', port=80): Max retries exceeded with url: /login/accounts/is_login/?bk_token=j1SM6C-otCNIRpJx_3UHhvZHSlQf1Dr5_whHUIIZKNc (Caused by <class 'socket.error'>: [Errno 111] Connection refused)
INFO [2018-02-05 21:09:52] /vagrant/testapp01/framework/account/accounts.py 86 verify_bk_login 13060 140521121142528 
 	 验证用户登录token无效： 

ERROR [2018-02-05 21:11:37] /vagrant/testapp01/framework/account/http.py 42 _http_request 13060 140521121142528 
 	 login http request error! type: GET, url: http://paaskghk.jingle.cn/login/accounts/is_login/, data: {'bk_token': '1uQO08z1vjFzS_mlXiZRCwEuxGxKeaNisARwVKZrG7M'} 
Traceback (most recent call last):
  File "/vagrant/testapp01/framework/account/http.py", line 30, in _http_request
    resp = requests.get(url=url, headers=headers, params=data)
  File "/usr/lib/python2.7/site-packages/requests/api.py", line 55, in get
    return request('get', url, **kwargs)
  File "/usr/lib/python2.7/site-packages/requests/api.py", line 44, in request
    return session.request(method=method, url=url, **kwargs)
  File "/usr/lib/python2.7/site-packages/requests/sessions.py", line 361, in request
    resp = self.send(prep, **send_kwargs)
  File "/usr/lib/python2.7/site-packages/requests/sessions.py", line 464, in send
    r = adapter.send(request, **kwargs)
  File "/usr/lib/python2.7/site-packages/requests/adapters.py", line 356, in send
    raise ConnectionError(e)
ConnectionError: HTTPConnectionPool(host='paaskghk.jingle.cn', port=80): Max retries exceeded with url: /login/accounts/is_login/?bk_token=1uQO08z1vjFzS_mlXiZRCwEuxGxKeaNisARwVKZrG7M (Caused by <class 'socket.error'>: [Errno 111] Connection refused)
INFO [2018-02-05 21:11:37] /vagrant/testapp01/framework/account/accounts.py 86 verify_bk_login 13060 140521121142528 
 	 验证用户登录token无效： 

ERROR [2018-02-05 21:11:52] /vagrant/testapp01/framework/account/http.py 42 _http_request 13060 140521121142528 
 	 login http request error! type: GET, url: http://paaskghk.jingle.cn/login/accounts/is_login/, data: {'bk_token': 'ARwAZ6hjDf7Hw0uCkaSWXM9ULnKK9Fal-WXU6bPKrZY'} 
Traceback (most recent call last):
  File "/vagrant/testapp01/framework/account/http.py", line 30, in _http_request
    resp = requests.get(url=url, headers=headers, params=data)
  File "/usr/lib/python2.7/site-packages/requests/api.py", line 55, in get
    return request('get', url, **kwargs)
  File "/usr/lib/python2.7/site-packages/requests/api.py", line 44, in request
    return session.request(method=method, url=url, **kwargs)
  File "/usr/lib/python2.7/site-packages/requests/sessions.py", line 361, in request
    resp = self.send(prep, **send_kwargs)
  File "/usr/lib/python2.7/site-packages/requests/sessions.py", line 464, in send
    r = adapter.send(request, **kwargs)
  File "/usr/lib/python2.7/site-packages/requests/adapters.py", line 356, in send
    raise ConnectionError(e)
ConnectionError: HTTPConnectionPool(host='paaskghk.jingle.cn', port=80): Max retries exceeded with url: /login/accounts/is_login/?bk_token=ARwAZ6hjDf7Hw0uCkaSWXM9ULnKK9Fal-WXU6bPKrZY (Caused by <class 'socket.error'>: [Errno 111] Connection refused)
INFO [2018-02-05 21:11:52] /vagrant/testapp01/framework/account/accounts.py 86 verify_bk_login 13060 140521121142528 
 	 验证用户登录token无效： 

ERROR [2018-02-05 21:14:21] /vagrant/testapp01/framework/account/http.py 42 _http_request 13353 140305028593408 
 	 login http request error! type: GET, url: http://paaskghk.jingle.cn/login/accounts/is_login/, data: {'bk_token': 'bDL6VpL0kW13ruN72htGJCAvYCvt_5HKsHclxYKMFdE'} 
Traceback (most recent call last):
  File "/vagrant/testapp01/framework/account/http.py", line 30, in _http_request
    resp = requests.get(url=url, headers=headers, params=data)
  File "/usr/lib/python2.7/site-packages/requests/api.py", line 55, in get
    return request('get', url, **kwargs)
  File "/usr/lib/python2.7/site-packages/requests/api.py", line 44, in request
    return session.request(method=method, url=url, **kwargs)
  File "/usr/lib/python2.7/site-packages/requests/sessions.py", line 361, in request
    resp = self.send(prep, **send_kwargs)
  File "/usr/lib/python2.7/site-packages/requests/sessions.py", line 464, in send
    r = adapter.send(request, **kwargs)
  File "/usr/lib/python2.7/site-packages/requests/adapters.py", line 356, in send
    raise ConnectionError(e)
ConnectionError: HTTPConnectionPool(host='paaskghk.jingle.cn', port=80): Max retries exceeded with url: /login/accounts/is_login/?bk_token=bDL6VpL0kW13ruN72htGJCAvYCvt_5HKsHclxYKMFdE (Caused by <class 'socket.error'>: [Errno 111] Connection refused)
INFO [2018-02-05 21:14:21] /vagrant/testapp01/framework/account/accounts.py 86 verify_bk_login 13353 140305028593408 
 	 验证用户登录token无效： 

